Workbook

Sheet 평가기준표
A1: No | B1: 클러스터 | C1: 세부 항목 | D1: 평가 설명 | E1: 데이터 소스 | F1: 적용 범위
A2: 1 | B2: 내용 충실도 | C2: 핵심 개념 커버리지 | D2: 발표자료의 핵심 개념을 발화에서 실제로 다뤘는가 (설명함/언급만/안나옴 판정) | E2: STT 전사본 + PPT | F2: 전체
A3: 2 | B3: 내용 충실도 | C3: 설명 깊이 | D3: 용어를 읽는 데 그치지 않고 의미·원리·관계까지 설명했는가 | E3: STT 전사본 | F3: 전체
A4: 3 | B4: 내용 충실도 | C4: 근거·수치·사례 제시 | D4: 주장에 필요한 근거·수치·사례가 제시됐는가 | E4: STT 전사본 | F4: 전체
A5: 4 | B5: 내용 충실도 | C5: 자료-발화 일치성 | D5: 슬라이드 자료와 실제 발화 사이 모순·누락이 없는가 | E5: STT 전사본 + PPT | F5: 전체
A6: 5 | B6: 내용 충실도 | C6: 근거 없는 추가 발화 | D6: 자료에 없는 내용을 근거 없이 임의로 덧붙이지 않았는가 | E6: STT 전사본 + PPT | F6: 전체
A7: 6 | B7: 내용 충실도 | C7: 선행연구·이론적 근거 인용 | D7: 관련 이론이나 선행 연구를 적절히 인용했는가 | E7: STT 전사본 | F7: 학교 프로젝트 전용
A8: 7 | B8: 논리 구조 | C8: 핵심 주장 제시 시점 | D8: 발표 목적/핵심 주장이 도입부에서 분명히 드러나는가 | E8: STT 전사본 | F8: 전체
A9: 8 | B9: 논리 구조 | C9: 주장-근거-결론 연결 | D9: 문제-원인-해결, 주장-근거-해석 관계가 논리적으로 유지되는가 | E9: STT 전사본 | F9: 전체
A10: 9 | B10: 논리 구조 | C10: 전제 생략·결론 점프·모순 | D10: 전제를 건너뛰거나 갑자기 결론으로 점프하지 않는가 | E10: STT 전사본 | F10: 전체
A11: 10 | B11: 논리 구조 | C11: 전환의 자연스러움 | D11: 슬라이드/구간 간 전환과 연결 표현이 논리 관계와 맞는가 | E11: STT 전사본 | F11: 전체
A12: 11 | B12: 논리 구조 | C12: 결론의 핵심 회수 | D12: 결론에서 앞의 핵심 내용을 다시 회수하는가 | E12: STT 전사본 | F12: 전체
A13: 12 | B13: 논리 구조 | C13: 두괄식 구조 | D13: 결론/핵심 메시지를 먼저 제시하고 근거를 뒤에 배치했는가 | E13: STT 전사본 | F13: 업무 보고 전용
... A40: 39 | B40: 시각자료 활용 | C40: 오탈자·맞춤법 | D40: 슬라이드 텍스트에 오탈자·맞춤법 오류가 없는가 | E40: PPT | F40: 전체

Sheet 클러스터_가중치
A1: 클러스터 | B1: 학교 프로젝트 (교수 대상) | C1: 신제품 설명 (대중 대상) | D1: 업무 보고 (상사 대상) | E1: 동료 간 캐주얼 PR
A2: 내용 충실도 | B2: 26 | C2: 17 | D2: 19 | E2: 28
A3: 논리 구조 | B3: 23 | C3: 15 | D3: 23 | E3: 20
A4: 목적·청중 적합성 | B4: 8 | C4: 19 | D4: 15 | E4: 8
A5: 언어적 명료성 | B5: 10 | C5: 12 | D5: 8 | E5: 11
A6: 음성적 전달 | B6: 7 | C6: 12 | D6: 6 | E6: 9
A7: 시각자료 활용 | B7: 13 | C7: 17 | D7: 11 | E7: 12
A8: 시간 관리 | B8: 13 | C8: 8 | D8: 18 | E8: 12
A9: 합계(검증, 100) | B9: =SUM(B2:B8) -> 100 | C9: =SUM(C2:C8) -> 100 | D9: =SUM(D2:D8) -> 100 | E9: =SUM(E2:E8) -> 100

Sheet 항목_내부가중치
A1: No | B1: 클러스터 | C1: 세부 항목 | D1: 학교 프로젝트 (교수 대상) | E1: 신제품 설명 (대중 대상) | F1: 업무 보고 (상사 대상) | G1: 동료 간 캐주얼 PR
A2: 1 | B2: 내용 충실도 | C2: 핵심 개념 커버리지 | D2: 9 | E2: 8 | F2: 8 | G2: 6
A3: 2 | B3: 내용 충실도 | C3: 설명 깊이 | D3: 10 | E3: 6 | F3: 6 | G3: 5
A4: 3 | B4: 내용 충실도 | C4: 근거·수치·사례 제시 | D4: 9 | E4: 7 | F4: 8 | G4: 5
A5: 4 | B5: 내용 충실도 | C5: 자료-발화 일치성 | D5: 8 | E5: 6 | F5: 7 | G5: 4
A6: 5 | B6: 내용 충실도 | C6: 근거 없는 추가 발화 | D6: 7 | E6: 5 | F6: 6 | G6: 3
A7: 6 | B7: 내용 충실도 | C7: 선행연구·이론적 근거 인용 | D7: 7 | E7: 0 | F7: 0 | G7: 0
A8: 7 | B8: 논리 구조 | C8: 핵심 주장 제시 시점 | D8: 6 | E8: 8 | F8: 9 | G8: 5
A9: 8 | B9: 논리 구조 | C9: 주장-근거-결론 연결 | D9: 9 | E9: 8 | F9: 9 | G9: 6
A10: 9 | B10: 논리 구조 | C10: 전제 생략·결론 점프·모순 | D10: 8 | E10: 7 | F10: 8 | G10: 5
A11: 10 | B11: 논리 구조 | C11: 전환의 자연스러움 | D11: 6 | E11: 6 | F11: 6 | G11: 4
A12: 11 | B12: 논리 구조 | C12: 결론의 핵심 회수 | D12: 6 | E12: 6 | F12: 7 | G12: 4
A13: 12 | B13: 논리 구조 | C13: 두괄식 구조 | D13: 0 | E13: 0 | F13: 8 | G13: 0
... A40: 39 | B40: 시각자료 활용 | C40: 오탈자·맞춤법 | D40: 4 | E40: 5 | F40: 5 | G40: 3
A42: ※ 값이 0(-)이면 해당 상황에서 그 항목은 평가하지 않습니다. 숫자는 같은 클러스터 안에서의 상대적 중요도(가중평균 가중치)이며, 100 합계일 필요는 없습니다.

Sheet 점수산정
A1: 1. 발표 상황 선택
B2: 상황 | C2: 학교 프로젝트 (교수 대상)
A4: 2. 항목별 채점 (0~100, 해당 상황에서 '-'로 표시된 항목은 채점 불필요)
A5: No | B5: 클러스터 | C5: 세부 항목 | D5: 적용 여부(내부가중치) | E5: 채점(0~100) | F5: 기여도
A6: 1 | B6: 내용 충실도 | C6: 핵심 개념 커버리지 | D6: =INDEX(항목_내부가중치!$D$2:$G$2,MATCH($C$2,항목_내부가중치!$D$1:$G$1,0)) -> 9 | E6: 0 | F6: =D6*E6 -> 0
A7: 2 | B7: 내용 충실도 | C7: 설명 깊이 | D7: =INDEX(항목_내부가중치!$D$3:$G$3,MATCH($C$2,항목_내부가중치!$D$1:$G$1,0)) -> 10 | E7: 0 | F7: =D7*E7 -> 0
A8: 3 | B8: 내용 충실도 | C8: 근거·수치·사례 제시 | D8: =INDEX(항목_내부가중치!$D$4:$G$4,MATCH($C$2,항목_내부가중치!$D$1:$G$1,0)) -> 9 | E8: 0 | F8: =D8*E8 -> 0
A9: 4 | B9: 내용 충실도 | C9: 자료-발화 일치성 | D9: =INDEX(항목_내부가중치!$D$5:$G$5,MATCH($C$2,항목_내부가중치!$D$1:$G$1,0)) -> 8 | E9: 0 | F9: =D9*E9 -> 0
A10: 5 | B10: 내용 충실도 | C10: 근거 없는 추가 발화 | D10: =INDEX(항목_내부가중치!$D$6:$G$6,MATCH($C$2,항목_내부가중치!$D$1:$G$1,0)) -> 7 | E10: 0 | F10: =D10*E10 -> 0
A11: 6 | B11: 내용 충실도 | C11: 선행연구·이론적 근거 인용 | D11: =INDEX(항목_내부가중치!$D$7:$G$7,MATCH($C$2,항목_내부가중치!$D$1:$G$1,0)) -> 7 | E11: 0 | F11: =D11*E11 -> 0
A12: 7 | B12: 논리 구조 | C12: 핵심 주장 제시 시점 | D12: =INDEX(항목_내부가중치!$D$8:$G$8,MATCH($C$2,항목_내부가중치!$D$1:$G$1,0)) -> 6 | E12: 0 | F12: =D12*E12 -> 0
A13: 8 | B13: 논리 구조 | C13: 주장-근거-결론 연결 | D13: =INDEX(항목_내부가중치!$D$9:$G$9,MATCH($C$2,항목_내부가중치!$D$1:$G$1,0)) -> 9 | E13: 0 | F13: =D13*E13 -> 0
A14: 9 | B14: 논리 구조 | C14: 전제 생략·결론 점프·모순 | D14: =INDEX(항목_내부가중치!$D$10:$G$10,MATCH($C$2,항목_내부가중치!$D$1:$G$1,0)) -> 8 | E14: 0 | F14: =D14*E14 -> 0
A15: 10 | B15: 논리 구조 | C15: 전환의 자연스러움 | D15: =INDEX(항목_내부가중치!$D$11:$G$11,MATCH($C$2,항목_내부가중치!$D$1:$G$1,0)) -> 6 | E15: 0 | F15: =D15*E15 -> 0
A16: 11 | B16: 논리 구조 | C16: 결론의 핵심 회수 | D16: =INDEX(항목_내부가중치!$D$12:$G$12,MATCH($C$2,항목_내부가중치!$D$1:$G$1,0)) -> 6 | E16: 0 | F16: =D16*E16 -> 0
A17: 12 | B17: 논리 구조 | C17: 두괄식 구조 | D17: =INDEX(항목_내부가중치!$D$13:$G$13,MATCH($C$2,항목_내부가중치!$D$1:$G$1,0)) -> 0 | E17: 0 | F17: =D17*E17 -> 0
A18: 13 | B18: 목적·청중 적합성 | C18: 청중 수준 맞춤 설명 | D18: =INDEX(항목_내부가중치!$D$14:$G$14,MATCH($C$2,항목_내부가중치!$D$1:$G$1,0)) -> 7 | E18: 0 | F18: =D18*E18 -> 0
A19: 14 | B19: 목적·청중 적합성 | C19: 목적에 맞는 강조점 | D19: =INDEX(항목_내부가중치!$D$15:$G$15,MATCH($C$2,항목_내부가중치!$D$1:$G$1,0)) -> 6 | E19: 0 | F19: =D19*E19 -> 0
A20: 15 | B20: 목적·청중 적합성 | C20: 흥미 유발·스토리텔링 | D20: =INDEX(항목_내부가중치!$D$16:$G$16,MATCH($C$2,항목_내부가중치!$D$1:$G$1,0)) -> 0 | E20: 0 | F20: =D20*E20 -> 0
A21: 16 | B21: 목적·청중 적합성 | C21: 실행 가능한 제안 명확성 | D21: =INDEX(항목_내부가중치!$D$17:$G$17,MATCH($C$2,항목_내부가중치!$D$1:$G$1,0)) -> 0 | E21: 0 | F21: =D21*E21 -> 0
A22: 17 | B22: 언어적 명료성 | C22: 지시어 남용 여부 | D22: =INDEX(항목_내부가중치!$D$18:$G$18,MATCH($C$2,항목_내부가중치!$D$1:$G$1,0)) -> 4 | E22: 0 | F22: =D22*E22 -> 0
A23: 18 | B23: 언어적 명료성 | C23: 전문용어 설명 동반 | D23: =INDEX(항목_내부가중치!$D$19:$G$19,MATCH($C$2,항목_내부가중치!$D$1:$G$1,0)) -> 6 | E23: 0 | F23: =D23*E23 -> 0
A24: 19 | B24: 언어적 명료성 | C24: 문장 길이·완결성 | D24: =INDEX(항목_내부가중치!$D$20:$G$20,MATCH($C$2,항목_내부가중치!$D$1:$G$1,0)) -> 4 | E24: 0 | F24: =D24*E24 -> 0
A25: 20 | B25: 언어적 명료성 | C25: 표현의 의미 없는 반복 | D25: =INDEX(항목_내부가중치!$D$21:$G$21,MATCH($C$2,항목_내부가중치!$D$1:$G$1,0)) -> 3 | E25: 0 | F25: =D25*E25 -> 0
A26: 21 | B26: 언어적 명료성 | C26: 핵심 구조 신호어 사용 | D26: =INDEX(항목_내부가중치!$D$22:$G$22,MATCH($C$2,항목_내부가중치!$D$1:$G$1,0)) -> 5 | E26: 0 | F26: =D26*E26 -> 0
A27: 22 | B27: 음성적 전달 | C27: 말속도 적절성 | D27: =INDEX(항목_내부가중치!$D$23:$G$23,MATCH($C$2,항목_내부가중치!$D$1:$G$1,0)) -> 4 | E27: 0 | F27: =D27*E27 -> 0
A28: 23 | B28: 음성적 전달 | C28: 필러 빈도·위치 | D28: =INDEX(항목_내부가중치!$D$24:$G$24,MATCH($C$2,항목_내부가중치!$D$1:$G$1,0)) -> 4 | E28: 0 | F28: =D28*E28 -> 0
A29: 24 | B29: 음성적 전달 | C29: 휴지·침묵의 위치 | D29: =INDEX(항목_내부가중치!$D$25:$G$25,MATCH($C$2,항목_내부가중치!$D$1:$G$1,0)) -> 3 | E29: 0 | F29: =D29*E29 -> 0
A30: 25 | B30: 음성적 전달 | C30: 음량 안정성 | D30: =INDEX(항목_내부가중치!$D$26:$G$26,MATCH($C$2,항목_내부가중치!$D$1:$G$1,0)) -> 3 | E30: 0 | F30: =D30*E30 -> 0
A31: 26 | B31: 음성적 전달 | C31: 핵심 구간 강조 | D31: =INDEX(항목_내부가중치!$D$27:$G$27,MATCH($C$2,항목_내부가중치!$D$1:$G$1,0)) -> 4 | E31: 0 | F31: =D31*E31 -> 0
A32: 27 | B32: 시각자료 활용 | C32: 낭독 vs 실제 설명 구분 | D32: =INDEX(항목_내부가중치!$D$28:$G$28,MATCH($C$2,항목_내부가중치!$D$1:$G$1,0)) -> 6 | E32: 0 | F32: =D32*E32 -> 0
A33: 28 | B33: 시각자료 활용 | C33: 슬라이드별 설명시간 균형 | D33: =INDEX(항목_내부가중치!$D$29:$G$29,MATCH($C$2,항목_내부가중치!$D$1:$G$1,0)) -> 5 | E33: 0 | F33: =D33*E33 -> 0
A34: 29 | B34: 시각자료 활용 | C34: 그래프·표 설명 | D34: =INDEX(항목_내부가중치!$D$30:$G$30,MATCH($C$2,항목_내부가중치!$D$1:$G$1,0)) -> 6 | E34: 0 | F34: =D34*E34 -> 0
A35: 30 | B35: 시각자료 활용 | C35: 슬라이드-발화 강조 일치 | D35: =INDEX(항목_내부가중치!$D$31:$G$31,MATCH($C$2,항목_내부가중치!$D$1:$G$1,0)) -> 5 | E35: 0 | F35: =D35*E35 -> 0
A36: 31 | B36: 시간 관리 | C36: 제한시간 준수 | D36: =INDEX(항목_내부가중치!$D$32:$G$32,MATCH($C$2,항목_내부가중치!$D$1:$G$1,0)) -> 5 | E36: 0 | F36: =D36*E36 -> 0
A37: 32 | B37: 시간 관리 | C37: 구간별 시간 배분 | D37: =INDEX(항목_내부가중치!$D$33:$G$33,MATCH($C$2,항목_내부가중치!$D$1:$G$1,0)) -> 5 | E37: 0 | F37: =D37*E37 -> 0
A38: 33 | B38: 시간 관리 | C38: 핵심 슬라이드 체류시간 | D38: =INDEX(항목_내부가중치!$D$34:$G$34,MATCH($C$2,항목_내부가중치!$D$1:$G$1,0)) -> 4 | E38: 0 | F38: =D38*E38 -> 0
A39: 34 | B39: 시각자료 활용 | C39: 슬라이드 정보 밀도 | D39: =INDEX(항목_내부가중치!$D$35:$G$35,MATCH($C$2,항목_내부가중치!$D$1:$G$1,0)) -> 5 | E39: 0 | F39: =D39*E39 -> 0
A40: 35 | B40: 시각자료 활용 | C40: 제목-본문 일치성 | D40: =INDEX(항목_내부가중치!$D$36:$G$36,MATCH($C$2,항목_내부가중치!$D$1:$G$1,0)) -> 5 | E40: 0 | F40: =D40*E40 -> 0
A41: 36 | B41: 시각자료 활용 | C41: 목차·로드맵 슬라이드 | D41: =INDEX(항목_내부가중치!$D$37:$G$37,MATCH($C$2,항목_내부가중치!$D$1:$G$1,0)) -> 4 | E41: 0 | F41: =D41*E41 -> 0
...
